Workbook
Name \: [1]metode!#REF!
Name \0: [2]A!$J$3
Name \1: '[3]AnalisaFas.O&P'!$O$8:$O$11
Name \a: #REF!
Name \b: #REF!
Name \c: #REF!
Name \D: '[3]AnalisaFas.O&P'!$O$23:$O$26
Name \E: '[3]AnalisaFas.O&P'!$O$28:$O$31
Name \F: '[3]AnalisaFas.O&P'!$O$33:$O$36
Name \G: '[3]AnalisaFas.O&P'!$O$38:$O$41
Name \H: '[3]AnalisaFas.O&P'!$O$43:$O$46
Name \i: #N/A
Name \J: '[3]AnalisaFas.O&P'!$O$53:$O$56
Name \K: '[3]AnalisaFas.O&P'!$O$58:$O$61
Name \L: '[3]AnalisaFas.O&P'!$O$63:$O$66
Name \M: [2]A!$J$40
Name \N: '[3]AnalisaFas.O&P'!$S$7:$S$10
Name \O: '[3]AnalisaFas.O&P'!$S$13:$S$16
Name \P: [2]A!$J$5
Name \q: #REF!
Name \R: '[3]AnalisaFas.O&P'!$S$28:$S$31
Name \S: [2]A!$J$34
Name \T: #REF!
Name \u: '[4]3'!#REF!
Name \v: '[4]3'!#REF!
Name \w: '[4]3'!#REF!
Name \x: #REF!
Name \y: '[4]3'!#REF!
Name \z: '[4]3'!#REF!
Name __?___RIGHT__?_: #REF!
Name ___________________________________PVC50: [5]DAF.HRG!$W$19
Name ___________________________________PVC75: [5]DAF.HRG!$W$18
Name __________________________________PVC50: [5]DAF.HRG!$W$19
Name __________________________________PVC75: [5]DAF.HRG!$W$18
Name _________________________________PVC50: [5]DAF.HRG!$W$19
Name _________________________________PVC75: [5]DAF.HRG!$W$18
Name ______________________________arr3: {"Book1","4.09 FLORA DAN FAUNA.xls","4.22 PERLENGKAPAN SEKOLAH.xls"}
Name ______________________________mas1: {"Book1","4.09 FLORA DAN FAUNA.xls","4.22 PERLENGKAPAN SEKOLAH.xls"}
Name ______________________________mas12: {"Book1","4.09 FLORA DAN FAUNA.xls","4.22 PERLENGKAPAN SEKOLAH.xls"}
Name ______________________________mas4: {"Book1","4.09 FLORA DAN FAUNA.xls","4.22 PERLENGKAPAN SEKOLAH.xls"}
Name ______________________________mas5: {"Book1","4.09 FLORA DAN FAUNA.xls","4.22 PERLENGKAPAN SEKOLAH.xls"}
Name ______________________________mas6: {"Book1","4.09 FLORA DAN FAUNA.xls","4.22 PERLENGKAPAN SEKOLAH.xls"}
Name ______________________________mas7: {"Book1","4.09 FLORA DAN FAUNA.xls","4.22 PERLENGKAPAN SEKOLAH.xls"}
Name ______________________________mas8: {"Book1","4.09 FLORA DAN FAUNA.xls","4.22 PERLENGKAPAN SEKOLAH.xls"}
Name ______________________________mas9: {"Book1","4.09 FLORA DAN FAUNA.xls","4.22 PERLENGKAPAN SEKOLAH.xls"}
Name ______________________________me1: {"Book1","4.09 FLORA DAN FAUNA.xls","4.22 PERLENGKAPAN SEKOLAH.xls"}
Name ______________________________me2: {"Book1","4.09 FLORA DAN FAUNA.xls","4.22 PERLENGKAPAN SEKOLAH.xls"}
Name ______________________________me3: {"Book1","4.09 FLORA DAN FAUNA.xls","4.22 PERLENGKAPAN SEKOLAH.xls"}
Name ______________________________me4: {"Book1","4.09 FLORA DAN FAUNA.xls","4.22 PERLENGKAPAN SEKOLAH.xls"}
Name ______________________________me5: {"Book1","4.09 FLORA DAN FAUNA.xls","4.22 PERLENGKAPAN SEKOLAH.xls"}
Name ______________________________mek3: {"Book1","4.09 FLORA DAN FAUNA.xls","4.22 PERLENGKAPAN SEKOLAH.xls"}
Name ______________________________mek5: {"Book1","4.09 FLORA DAN FAUNA.xls","4.22 PERLENGKAPAN SEKOLAH.xls"}
Name _____________________________arr3: {"Book1","4.09 FLORA DAN FAUNA.xls","4.22 PERLENGKAPAN SEKOLAH.xls"}
Name _____________________________der4: {"Book1","4.09 FLORA DAN FAUNA.xls","4.22 PERLENGKAPAN SEKOLAH.xls"}
Name _____________________________mas1: {"Book1","4.09 FLORA DAN FAUNA.xls","4.22 PERLENGKAPAN SEKOLAH.xls"}
Name _____________________________mas12: {"Book1","4.09 FLORA DAN FAUNA.xls","4.22 PERLENGKAPAN SEKOLAH.xls"}
Name _____________________________mas2: {"Book1","4.09 FLORA DAN FAUNA.xls","4.22 PERLENGKAPAN SEKOLAH.xls"}
Name _____________________________mas4: {"Book1","4.09 FLORA DAN FAUNA.xls","4.22 PERLENGKAPAN SEKOLAH.xls"}
Name _____________________________mas5: {"Book1","4.09 FLORA DAN FAUNA.xls","4.22 PERLENGKAPAN SEKOLAH.xls"}
Name _____________________________mas6: {"Book1","4.09 FLORA DAN FAUNA.xls","4.22 PERLENGKAPAN SEKOLAH.xls"}

Sheet REKAP ANALISA
B1: REKAP ANALISIS HARGA SATUAN PEKERJAAN (AHSP) BIDANG CIPTA KARYA
B5: HARGA SATUAN PEKERJAAN
B6: No | C6: Kode | E6: Jenis Pekerjaan | F6: Satuan | G6: Harga
B7: PP | C7: A.2.2.1 | D7: HARGA SATUAN PEKERJAAN PERSIAPAN
B8: 1 | C8: PP1 | D8: A.2.2.1.1. | E8: (K3) Pembuatan 1 m2 pagar sementara dari kayu tinggi 2 meter | F8: m2 | G8: =VLOOKUP(C8,ANALISA!$B:$I,8,0) -> 709983.77
B9: 2 | C9: PP2 | D9: A.2.2.1.2 | E9: (K3) Pembuatan 1 m2 pagar sementara dari seng gelombang tinggi 2 meter | F9: m2 | G9: =VLOOKUP(C9,ANALISA!$B:$I,8,0) -> 873324.92
B10: 3 | C10: PP3 | D10: A.2.2.1.3. | E10: Pembuatan 1 m2 pagar sementara dari kawat duri tinggi 1,8 meter | F10: m2 | G10: =VLOOKUP(C10,ANALISA!$B:$I,8,0) -> 456915.69
B11: 4 | C11: PP4 | D11: A.2.2.1.4. | E11: Pengukuran dan pemasangan 1 m’ Bouwplank | F11: m' | G11: =VLOOKUP(C11,ANALISA!$B:$I,8,0) -> 216295.68
B12: 5 | C12: PP5 | D12: A.2.2.1.5. | E12: (K3) Pembuatan 1 m2 kantor sementara lantai plesteran | F12: m2 | G12: =VLOOKUP(C12,ANALISA!$B:$I,8,0) -> 2700456.1
B13: 6 | C13: PP6 | D13: A.2.2.1.6. | E13: (K3) Pembuatan 1 m2 rumah jaga (konstruksi kayu ) | F13: m2 | G13: =VLOOKUP(C13,ANALISA!$B:$I,8,0) -> 2969699.1
B14: 7 | C14: PP7 | D14: A.2.2.1.7. | E14: (K3) Pembuatan 1 m2 gudang semen dan peralatan | F14: m2 | G14: =VLOOKUP(C14,ANALISA!$B:$I,8,0) -> 2510998.2
B15: 8 | C15: PP8 | D15: A.2.2.1.8. | E15: (K3) Pembuatan 1 m2 bedeng pekerja | F15: m2 | G15: =VLOOKUP(C15,ANALISA!$B:$I,8,0) -> 2364978.8
B16: 9 | C16: PP9 | D16: A.2.2.1.9. | E16: (K3) Pembersihan 1 m2 lapangan dan perataan | F16: m2 | G16: =VLOOKUP(C16,ANALISA!$B:$I,8,0) -> 16260.75
B17: 10 | C17: PP10 | D17: A.2.2.1.10. | E17: (K3) Pembuatan 1 m2 steger/perancah dari bambu | F17: m2 | G17: =VLOOKUP(C17,ANALISA!$B:$I,8,0) -> 384382.45
B18: 11 | C18: PP11 | D18: A.2.2.1.11. | E18: Pembuatan 1 buah kotak adukan ukuran 40cm x50cm x25cm | F18: Buah | G18: =VLOOKUP(C18,ANALISA!$B:$I,8,0) -> 164795.31
B19: 12 | C19: PP12 | D19: A.2.2.1.12. | E19: Pembuatan 1 m2 jalan sementara | F19: m2 | G19: =VLOOKUP(C19,ANALISA!$B:$I,8,0) -> 165836.65
... B23: 16 | C23: PP16 | D23: A.2.2.1.16. | E23: Pemasangan 1 m2 panel beton pracetak 5x50x240 cm | F23: m2 | G23: =VLOOKUP(C23,ANALISA!$B:$I,8,0) -> 2163793.6
B25: PT | C25: A.2.3.1 | D25: HARGA SATUAN PEKERJAAN TANAH
B26: 17 | C26: PT1 | D26: A.2.3.1.1. | E26: Penggalian 1 m3 tanah biasa sedalam 1 m | F26: m3 | G26: =VLOOKUP(C26,ANALISA!$B:$I,8,0) -> 79414.875
B27: 18 | C27: PT2 | D27: A.2.3.1.2. | E27: Penggalian 1 m3 tanah biasa sedalam 2 m | F27: m3 | G27: =VLOOKUP(C27,ANALISA!$B:$I,8,0) -> 97121.025
B28: 19 | C28: PT3 | D28: A.2.3.1.3. | E28: Menggali 1 m3 tanah biasa sedalam 3 m | F28: m3 | G28: =VLOOKUP(C28,ANALISA!$B:$I,8,0) -> 115070.26
B29: 20 | C29: PT4 | D29: A.2.3.1.4. | E29: Menggali 1 m3 tanah keras sedalam 1 m | F29: m3 | G29: =VLOOKUP(C29,ANALISA!$B:$I,8,0) -> 105724.44
B30: 21 | C30: PT5 | D30: A.2.3.1.5. | E30: Menggali 1 m3 tanah cadas sedalam 1 m | F30: m3 | G30: =VLOOKUP(C30,ANALISA!$B:$I,8,0) -> 160045.2
B31: 22 | C31: PT6 | D31: A.2.3.1.6. | E31: Menggali 1 m3 tanah lumpur sedalam 1 m | F31: m3 | G31: =VLOOKUP(C31,ANALISA!$B:$I,8,0) -> 127671.52
B32: 23 | C32: PT7 | D32: A.2.3.1.7. | E32: Pengerjaan stripping 1 m2 tanah tebing setinggi 1 meter | F32: m2 | G32: =VLOOKUP(C32,ANALISA!$B:$I,8,0) -> 5699.475
B33: 24 | C33: PT8 | D33: A.2.3.1.8. | E33: (K3) Pembuangan 1 m3 tanah sejauh 30 meter | F33: m3 | G33: =VLOOKUP(C33,ANALISA!$B:$I,8,0) -> 34821
B34: 25 | C34: PT9 | D34: A.2.3.1.9. | E34: Pengurugan kembali 1 m3 galian tanah (1/3 Galian;-Tanah Biasa Sedalam 1 M) | F34: m3 | G34: =VLOOKUP(C34,ANALISA!$B:$I,8,0) -> 28497.375
B35: 26 | C35: PT10 | D35: A.2.3.1.10. | E35: (K3) Pemadatan tanah 1 m3 tanah ( per 20 cm) | F35: m3 | G35: =VLOOKUP(C35,ANALISA!$B:$I,8,0) -> 56994.75
B36: 27 | C36: PT11 | D36: A.2.3.1.11. | E36: Pengurugan 1 m3 dengan pasir urug | F36: m3 | G36: =VLOOKUP(C36,ANALISA!$B:$I,8,0) -> 163560.15
B37: 28 | C37: PT12 | D37: A.2.3.1.12. | E37: Pemasangan 1 m3 lapisan pudel campuran 1KP:3PP:7TL | F37: m3 | G37: =VLOOKUP(C37,ANALISA!$B:$I,8,0) -> 326789.83
... B39: 30 | C39: PT14 | D39: A.2.3.1.14. | E39: Pengurugan 1 m3 sirtu padat | F39: m3 | G39: =VLOOKUP(C39,ANALISA!$B:$I,8,0) -> 210486.38
B41: PD | C41: A.3.2.2 | D41: HARGA SATUAN PEKERJAAN PONDASI
B42: 31 | C42: PD1 | D42: A.3.2.1.1. | E42: Pemasangan 1 m3 pondasi batu belah campuran 1SP : 3PP | F42: m3 | G42: =VLOOKUP(C42,ANALISA!$B:$I,8,0) -> 877049.56
B43: 32 | C43: PD2 | D43: A.3.2.1.2. | E43: Pemasangan 1 m3 pondasi batu belah campuran 1SP : 4PP | F43: m3 | G43: =VLOOKUP(C43,ANALISA!$B:$I,8,0) -> 828692.71
B44: 33 | C44: PD3 | D44: A.3.2.1.3. | E44: Pemasangan 1 m3 pondasi batu belah campuran 1SP : 5PP | F44: m3 | G44: =VLOOKUP(C44,ANALISA!$B:$I,8,0) -> 795181.77
B45: 34 | C45: PD4 | D45: A.3.2.1.4. | E45: Pemasangan 1 m3 pondasi batu belah campuran 1SP : 6PP | F45: m3 | G45: =VLOOKUP(C45,ANALISA!$B:$I,8,0) -> 771615.95
B46: 35 | C46: PD5 | D46: A.3.2.1.5. | E46: Pemasangan 1 m3 pondasi batu belah campuran 1SP : 8PP | F46: m3 | G46: =VLOOKUP(C46,ANALISA!$B:$I,8,0) -> 739330.2
B47: 36 | C47: PD6 | D47: A.3.2.1.6. | E47: Pemasangan 1 m3 pondasi batu belah campuran 1SP : 1KP : 2PP | F47: m3 | G47: =VLOOKUP(C47,ANALISA!$B:$I,8,0) -> 833245.72
B48: 37 | C48: PD7 | D48: A.3.2.1.7. | E48: Pemasangan 1 m3 pondasi batu belah campuran 1 SP : 3 KP : 10 PP | F48: m3 | G48: =VLOOKUP(C48,ANALISA!$B:$I,8,0) -> 703056.58
B49: 38 | C49: PD8 | D49: A.3.2.1.8. | E49: Pemasangan 1 m3 pondasi batu belah campuran ¼ SP : 1 KP : 4PP | F49: m3 | G49: =VLOOKUP(C49,ANALISA!$B:$I,8,0) -> 678173.03
...

Sheet ANALISA
C3: ANALISIS HARGA SATUAN PEKERJAAN (AHSP) BIDANG CIPTA KARYA | K3: OVERHEAD | L3: 0.095 | M3: PP | N3: HARGA SATUAN PEKERJAAN PERSIAPAN
M4: PT | N4: HARGA SATUAN PEKERJAAN TANAH
M5: PD | N5: HARGA SATUAN PEKERJAAN PONDASI
C6: ='REKAP ANALISA'!D7 -> HARGA SATUAN PEKERJAAN PERSIAPAN | M6: PB | N6: HARGA SATUAN PEKERJAAN BETON
C7: =VLOOKUP(B28,'REKAP ANALISA'!$C:$G,3,0) -> (K3) Pembuatan 1 m2 pagar sementara dari kayu tinggi 2 meter | M7: PBA | N7: HARGA SATUAN PEKERJAAN BESI DAN ALUMUNIUM
C8: No | D8: Uraian | E8: Kode | F8: Satuan | G8: Koefisien | H8: Harga Satuan | I8: Jumlah Harga | M8: PPD | N8: HARGA SATUAN PEKERJAAN PASANGAN DINDING
C9: A | D9: TENAGA | M9: PPT | N9: HARGA SATUAN PEKERJAAN PLESTERAN
D10: Pekerja | E10: L.01 | F10: OH | G10: 0.4 | H10: =VLOOKUP(E10,UPAH!$C:$F,4,0) -> 93000 | I10: =+G10*H10 -> 37200 | M10: PPL | N10: HARGA SATUAN PEKERJAAN PENUTUP LANTAI DAN PENUTUP DINDING
D11: Tukang Kayu | E11: L.02 | F11: OH | G11: 0.2 | H11: =VLOOKUP(E11,UPAH!$C:$F,4,0) -> 98000 | I11: =+G11*H11 -> 19600 | M11: PLL | N11: HARGA SATUAN PEKERJAAN LANGIT-LANGIT (PLAFOND)
D12: Kepala Tukang | E12: L.03 | F12: OH | G12: 0.02 | H12: =VLOOKUP(E12,UPAH!$C:$F,4,0) -> 106000 | I12: =+G12*H12 -> 2120 | M12: PPA | N12: HARGA SATUAN PEKERJAAN PENUTUP ATAP
D13: Mandor | E13: L.04 | F13: OH | G13: 0.02 | H13: =VLOOKUP(E13,UPAH!$C:$F,4,0) -> 111000 | I13: =+G13*H13 -> 2220 | M13: PK | N13: HARGA SATUAN PEKERJAAN KAYU
F14: JUMLAH TENAGA KERJA | I14: =SUM(I10:I13) -> 61140 | M14: PKK | N14: HARGA SATUAN PEKERJAAN KUNCI DAN KACA
C15: B | D15: BAHAN | M15: PC | N15: HARGA SATUAN PEKERJAAN PENGECATAN
D16: Dolken kayu Ø 8-10/400 cm | E16: M.74 | F16: =VLOOKUP(E16,MATERIAL!$C:$F,3,0) -> Batang | G16: 1.25 | H16: =VLOOKUP(E16,MATERIAL!$C:$F,4,0) -> 62000 | I16: =+G16*H16 -> 77500 | M16: PSD | N16: HARGA SATUAN PEKERJAAN SANITASI DALAM GEDUNG
D17: Semen portland | E17: M.11 | F17: =VLOOKUP(E17,MATERIAL!$C:$F,3,0) -> Kg | G17: 5 | H17: =VLOOKUP(E17,MATERIAL!$C:$F,4,0) -> 1250 | I17: =+G17*H17 -> 6250 | M17: PPP | N17: HARGA SATUAN PEKERJAAN PEMASANGAN PIPA
D18: Pasir beton | E18: M.46 | F18: =VLOOKUP(E18,MATERIAL!$C:$F,3,0) -> m3 | G18: 0.005 | H18: =VLOOKUP(E18,MATERIAL!$C:$F,4,0) -> 103800 | I18: =+G18*H18 -> 519 | M18: PTP | N18: HARGA SATUAN PEKERJAAN PEMOTONGAN PIPA
D19: Koral beton | E19: M.488 | F19: =VLOOKUP(E19,MATERIAL!$C:$F,3,0) -> m3 | G19: 0.009 | H19: =VLOOKUP(E19,MATERIAL!$C:$F,4,0) -> 148400 | I19: =+G19*H19 -> 1335.6 | M19: PAP | N19: HARGA SATUAN PEKERJAAN PEMASANGAN AKSESORIS PIPA
D20: Kayu 5/7 | E20: M.489 | F20: =VLOOKUP(E20,MATERIAL!$C:$F,3,0) -> m3 | G20: 0.072 | H20: =VLOOKUP(E20,MATERIAL!$C:$F,4,0) -> 6871700 | I20: =+G20*H20 -> 494762.4 | M20: PSB | N20: HARGA SATUAN PEKERJAAN PENYAMBUNGAN PIPA BARU KE PIPA LAMA
D21: Paku biasa | E21: M.200 | F21: =VLOOKUP(E21,MATERIAL!$C:$F,3,0) -> Kg | G21: 0.06 | H21: =VLOOKUP(E21,MATERIAL!$C:$F,4,0) -> 18000 | I21: =+G21*H21 -> 1080 | M21: PTS | N21: HARGA SATUAN PEKERJAAN PENGETESAN PIPA
D22: Residu | E22: M.490 | F22: =VLOOKUP(E22,MATERIAL!$C:$F,3,0) -> Liter | G22: 0.4 | H22: =VLOOKUP(E22,MATERIAL!$C:$F,4,0) -> 14500 | I22: =+G22*H22 -> 5800 | M22: PKL | N22: HARGA SATUAN PEKERJAAN ELEKTRIKAL
F23: JUMLAH HARGA BAHAN | I23: =SUM(I16:I22) -> 587247
C24: C | D24: PERALATAN
F25: JUMLAH HARGA ALAT
C26: D | D26: Jumlah (A+B+C) | I26: =I14+I23 -> 648387
C27: E | D27: =+"Overhead & Profit "&$L$3*100&"%" -> Overhead & Profit 9,5% | G27: =$L$3 -> 0.095 | I27: =G27*I26 -> 61596.765
B28: =$M$3&1 -> PP1 | C28: F | D28: Harga Satuan Pekerjaan (D+E) | I28: =SUM(I26:I27) -> 709983.77 | J28: 1
C30: =VLOOKUP(B52,'REKAP ANALISA'!$C:$G,3,0) -> (K3) Pembuatan 1 m2 pagar sementara dari seng gelombang tinggi 2 meter
C31: No | D31: Uraian | E31: Kode | F31: Satuan | G31: Koefisien | H31: Harga Satuan | I31: Jumlah Harga
C32: A | D32: TENAGA
D33: Pekerja | E33: L.01 | F33: OH | G33: 0.2 | H33: =VLOOKUP(E33,UPAH!$C:$F,4,0) -> 93000 | I33: =+G33*H33 -> 18600
D34: Tukang Kayu | E34: L.02 | F34: OH | G34: 0.4 | H34: =VLOOKUP(E34,UPAH!$C:$F,4,0) -> 98000 | I34: =+G34*H34 -> 39200
D35: Kepala Tukang | E35: L.03 | F35: OH | G35: 0.02 | H35: =VLOOKUP(E35,UPAH!$C:$F,4,0) -> 106000 | I35: =+G35*H35 -> 2120
D36: Mandor | E36: L.04 | F36: OH | G36: 0.02 | H36: =VLOOKUP(E36,UPAH!$C:$F,4,0) -> 111000 | I36: =+G36*H36 -> 2220
F37: JUMLAH TENAGA KERJA | I37: =SUM(I33:I36) -> 62140
C38: B | D38: BAHAN
D39: Dolken kayu Ø 8-10/400 cm | E39: M.74 | F39: =VLOOKUP(E39,MATERIAL!$C:$F,3,0) -> Batang | G39: 1.25 | H39: =VLOOKUP(E39,MATERIAL!$C:$F,4,0) -> 62000 | I39: =+G39*H39 -> 77500
D40: Semen portland | E40: M.11 | F40: =VLOOKUP(E40,MATERIAL!$C:$F,3,0) -> Kg | G40: 2.5 | H40: =VLOOKUP(E40,MATERIAL!$C:$F,4,0) -> 1250 | I40: =+G40*H40 -> 3125
D41: Seng gelombang | E41: M.271 | F41: =VLOOKUP(E41,MATERIAL!$C:$F,3,0) -> Lembar | G41: 1.2 | H41: =VLOOKUP(E41,MATERIAL!$C:$F,4,0) -> 106800 | I41: =+G41*H41 -> 128160
D42: Pasir beton | E42: M.46 | F42: =VLOOKUP(E42,MATERIAL!$C:$F,3,0) -> m3 | G42: 0.005 | H42: =VLOOKUP(E42,MATERIAL!$C:$F,4,0) -> 103800 | I42: =+G42*H42 -> 519
D43: Koral beton | E43: M.488 | F43: =VLOOKUP(E43,MATERIAL!$C:$F,3,0) -> m3 | G43: 0.009 | H43: =VLOOKUP(E43,MATERIAL!$C:$F,4,0) -> 148400 | I43: =+G43*H43 -> 1335.6
...

Sheet UPAH
B1: HARGA SATUAN DASAR TENAGA KERJA KABUPATEN JEMBER
B3: No | C3: Kode | D3: Uraian | E3: Satuan | F3: Harga Satuan Dasar (HSD) (Rp.) | G3: Keterangan
B4: 1 | C4: 2 | D4: 3 | E4: 4 | F4: 5 | G4: 6
B5: I | D5: UPAH TENAGA KERJA
B6: 1 | C6: L.01 | D6: Pekerja | E6: OH | F6: 93000
B7: 2 | C7: L.02 | D7: Tukang | E7: OH | F7: =+F6+5000 -> 98000
B8: 3 | C8: L.03 | D8: Kepala Tukang | E8: OH | F8: =+F7+8000 -> 106000
B9: 4 | C9: L.04 | D9: Mandor | E9: OH | F9: =+F8+5000 -> 111000
B10: 5 | C10: L.05 | D10: Juru Ukur, Operator/Mekanik Alat Berat/Teknisi | E10: OH | F10: 158700
B11: 6 | C11: L.06 | D11: Pembantu Juru Ukur & Operator/Mekanik Alat Berat | E11: OH | F11: 119100
B12: 7 | C12: L.07 | D12: Ahli Muda | E12: OH | F12: 158800
B13: 8 | C13: L.08 | D13: Ahli Madya | E13: OH | F13: 317500
B14: 9 | C14: L.09 | D14: Ahli Utama | E14: OH | F14: 555700
B15: 10 | C15: L.10 | D15: Supir Truck | E15: OH | F15: 141700
B16: 11 | C16: L.11 | D16: Supir Kendaraan < 2 Ton (Termasuk Sedan) | E16: OH | F16: 141700
B17: 12 | C17: L.12 | D17: Kenek | E17: OH | F17: 113300
B18: 13 | C18: L.13 | D18: Penjaga Malam/Satpam | E18: OH | F18: 79400
B19: 14 | C19: L.14 | D19: Drafter Cad/Manual | E19: OH | F19: 119100
B20: 15 | C20: L.15 | D20: Desain Engineer | E20: OH | F20: 158800
B21: 16 | C21: L.16 | D21: Operator Komputer/Printer/Ploter | E21: OH | F21: 119100
B22: 17 | C22: L.01.a | D22: Pekerja | E22: Jam | F22: =+F6/8 -> 11625
B23: 18 | C23: L.02.a | D23: Tukang | E23: Jam | F23: =+F7/8 -> 12250
B24: 19 | C24: L.03.a | D24: Kepala Tukang | E24: Jam | F24: =+F8/8 -> 13250
B25: 20 | C25: L.04.a | D25: Mandor | E25: Jam | F25: =+F9/8 -> 13875
B26: 21 | C26: L.05.a | D26: Juru Ukur, Operator/Mekanik Alat Berat/Teknisi | E26: Jam | F26: =+F10/8 -> 19837.5
B27: 22 | C27: L.06.a | D27: Pembantu Juru Ukur & Operator/Mekanik Alat Berat | E27: Jam | F27: =+F11/8 -> 14887.5
B28: 23 | C28: L.07.a | D28: Ahli Muda | E28: Jam | F28: 22685.71
B29: 24 | C29: L.08.a | D29: Ahli Madya | E29: Jam | F29: 45357.14
B30: 25 | C30: L.09.a | D30: Ahli Utama | E30: Jam | F30: 79385.71
B31: 26 | C31: L.10.a | D31: Supir Truck | E31: Jam | F31: 20242.86
B32: 27 | C32: L.11.a | D32: Supir Kendaraan < 2 Ton (Termasuk Sedan) | E32: Jam | F32: 20242.86
B33: 28 | C33: L.12.a | D33: Kenek | E33: Jam | F33: 16185.71
B34: 29 | C34: L.13.a | D34: Penjaga Malam/Satpam | E34: Jam | F34: 11342.86
B35: 30 | C35: L.14.a | D35: Drafter Cad/Manual | E35: Jam | F35: 17014.29
B36: 31 | C36: L.15.a | D36: Desain Engineer | E36: Jam | F36: 22685.71
B37: 32 | C37: L.16.a | D37: Operator Komputer/Printer/Ploter | E37: Jam | F37: 17014.29

Sheet MATERIAL
B1: HARGA SATUAN DASAR BAHAN BANGUNAN KABUPATEN JEMBER
B3: No | C3: Kode | D3: Uraian | E3: Satuan | F3: Harga Satuan (Rp.) | G3: Keterangan
B4: A | D4: KELOMPOK AIR, TANAH, BATU DAN SEMEN
B5: 1 | C5: M.01 | D5: Abu Batu | E5: m3 | F5: 293400
B6: 2 | C6: M.02 | D6: Air | E6: m3 | F6: 1
B7: 3 | C7: M.03 | D7: Ampelas Halus | E7: m' | F7: 15400
B8: 4 | C8: M.04 | D8: Ampelas Sedang | E8: m' | F8: 13000
B9: 5 | C9: M.05 | D9: Ampelas Kasar | E9: m' | F9: 10700
B10: 6 | C10: M.06 | D10: Bahan Aditif (Caldbon, Strorox, Dan Lain-Lain) | E10: L | F10: 76200
B11: 7 | C11: M.07 | D11: Batu Bata / Merah Bakar Kelas I | E11: Buah | F11: 700
B12: 8 | C12: M.08 | D12: Batu Bata / Merah Bakar Kelas Ii | E12: Buah | F12: 600
B13: 9 | C13: M.09 | D13: Batu Bata / Merah Bakar Kw Biasa | E13: Buah | F13: 600
B14: 10 | C14: M.10 | D14: Batu Bata / Merah Bakar Pres | E14: Buah | F14: 700
B15: 11 | C15: M.11 | D15: Portland Cement | E15: Kg | F15: 1250
B16: 12 | C16: M.12 | D16: Batu / Batu Kali/ Batu Belah | E16: m3 | F16: 277500
... B75: 71 | C75: M.71 | D75: Turap Beton Tulang Pre-Cast 22X50 Cm | E75: m | F75: 545100
F76: -
B77: B | D77: Kelompok Kayu | F77: -
B78: 1 | C78: M.72 | D78: Bambu Ø 2", Panjang 4 M | E78: Batang | F78: 16600
B79: 2 | C79: M.73 | D79: Bambu ø 8 - 10 cm | E79: Batang | F79: 27900
B80: 3 | C80: M.74 | D80: Dolken Kayu Galam Ø 8-10 Cm, Panjang 4M (Tiang Pancang) | E80: Batang | F80: 62000
B81: 4 | C81: M.75 | D81: Dolken Kayu Galam Ø 6-8 Cm, Panjang 4M (Tiang Pancang) | E81: Batang | F81: 98300
B82: 5 | C82: M.76 | D82: Dolken Kayu Klas Iii Ø 5 - 7 Cm, Panjang 3 M (Stoot) | E82: Batang | F82: 25400
B83: 6 | C83: M.77 | D83: Dolken Kayu Klas Iii Ø 7 -10 Cm, Panjang 4 M (Stoot) | E83: Batang | F83: 44600
B84: 7 | C84: M.78 | D84: Ijuk Tebal 5 Cm | E84: Kg | F84: 14000
B85: 8 | C85: M.79 | D85: Kayu Balok Kelas 1 | E85: m3 | F85: 8811600
B86: 9 | C86: M.80 | D86: Kayu Papan Kelas 1 | E86: m3 | F86: 10102300
B87: 10 | C87: M.81 | D87: Kayu Jati Balok Kualitas Tinggi | E87: m3 | F87: 11247600
B88: 11 | C88: M.82 | D88: Kayu Jati Balok Kualitas Sedang | E88: m3 | F88: 8624200
B89: 12 | C89: M.83 | D89: Kayu Jati Papan Kualitas Tinggi | E89: m3 | F89: 13845000
... B122: 45 | C122: M.116 | D122: Tusuk Bamboo | E122: Buah | F122: 1500
F123: -
D124: Kelompok Logam | F124: -
B125: 1 | C125: M.117 | D125: Alat Penyambung Tiang Pancang Kayu Gelondongan | E125: Buah | F125: 111300
B126: 2 | C126: M.118 | D126: Alat Penyambung Turap Papan Kayu 3/10 Cm | E126: Buah | F126: 13800
B127: 3 | C127: M.119 | D127: Alat Penyambung Turap Papan Kayu 3/20 Cm | E127: Buah | F127: 27600
B128: 4 | C128: M.120 | D128: Alat Penyambung Turap Papan Kayu 3/25 Cm | E128: Buah | F128: 41800
B129: 5 | C129: M.121 | D129: Alat Penyambung Turap Papan Kayu 3/30 Cm | E129: Buah | F129: 56200
B130: 6 | C130: M.122 | D130: Alat Penyambung Tiang Pancang Dolken | E130: Buah | F130: 21100
B131: 7 | C131: M.123 | D131: Alat Penyambung Tiang Pancang Kaso 5/7 | E131: Buah | F131: 15600
...
